2022-11-07 09:10:07,763 INFO    StreamThr :2632 [internal.py:wandb_internal():88] W&B internal server running at pid: 2632, started at: 2022-11-07 09:10:07.763676
2022-11-07 09:10:07,763 DEBUG   HandlerThread:2632 [handler.py:handle_request():139] handle_request: status
2022-11-07 09:10:07,779 DEBUG   SenderThread:2632 [sender.py:send_request():317] send_request: status
2022-11-07 09:10:07,779 DEBUG   SenderThread:2632 [sender.py:send():303] send: header
2022-11-07 09:10:07,779 INFO    WriterThread:2632 [datastore.py:open_for_write():75] open: C:\Users\wwwle\Documents\Materias_Universidad\Redes Neuronales\Proyecto-2_RNA\Red Neuronal\wandb\run-20221107_091007-3qxvuv2l\run-3qxvuv2l.wandb
2022-11-07 09:10:07,941 DEBUG   SenderThread:2632 [sender.py:send():303] send: run
2022-11-07 09:10:11,206 ERROR   SenderThread:2632 [retry.py:__call__():154] Retry attempt failed:
Traceback (most recent call last):
  File "C:\Users\wwwle\Documents\Materias_Universidad\Redes Neuronales\env\Keras[3.9]\lib\site-packages\urllib3\connection.py", line 174, in _new_conn
    conn = connection.create_connection(
  File "C:\Users\wwwle\Documents\Materias_Universidad\Redes Neuronales\env\Keras[3.9]\lib\site-packages\urllib3\util\connection.py", line 72, in create_connection
    for res in socket.getaddrinfo(host, port, family, socket.SOCK_STREAM):
  File "C:\Python\Python 3.9\lib\socket.py", line 954, in getaddrinfo
    for res in _socket.getaddrinfo(host, port, family, type, proto, flags):
socket.gaierror: [Errno 11001] getaddrinfo failed

During handling of the above exception, another exception occurred:

Traceback (most recent call last):
  File "C:\Users\wwwle\Documents\Materias_Universidad\Redes Neuronales\env\Keras[3.9]\lib\site-packages\urllib3\connectionpool.py", line 703, in urlopen
    httplib_response = self._make_request(
  File "C:\Users\wwwle\Documents\Materias_Universidad\Redes Neuronales\env\Keras[3.9]\lib\site-packages\urllib3\connectionpool.py", line 386, in _make_request
    self._validate_conn(conn)
  File "C:\Users\wwwle\Documents\Materias_Universidad\Redes Neuronales\env\Keras[3.9]\lib\site-packages\urllib3\connectionpool.py", line 1042, in _validate_conn
    conn.connect()
  File "C:\Users\wwwle\Documents\Materias_Universidad\Redes Neuronales\env\Keras[3.9]\lib\site-packages\urllib3\connection.py", line 358, in connect
    self.sock = conn = self._new_conn()
  File "C:\Users\wwwle\Documents\Materias_Universidad\Redes Neuronales\env\Keras[3.9]\lib\site-packages\urllib3\connection.py", line 186, in _new_conn
    raise NewConnectionError(
urllib3.exceptions.NewConnectionError: <urllib3.connection.HTTPSConnection object at 0x0000019319B49430>: Failed to establish a new connection: [Errno 11001] getaddrinfo failed

During handling of the above exception, another exception occurred:

Traceback (most recent call last):
  File "C:\Users\wwwle\Documents\Materias_Universidad\Redes Neuronales\env\Keras[3.9]\lib\site-packages\requests\adapters.py", line 489, in send
    resp = conn.urlopen(
  File "C:\Users\wwwle\Documents\Materias_Universidad\Redes Neuronales\env\Keras[3.9]\lib\site-packages\urllib3\connectionpool.py", line 787, in urlopen
    retries = retries.increment(
  File "C:\Users\wwwle\Documents\Materias_Universidad\Redes Neuronales\env\Keras[3.9]\lib\site-packages\urllib3\util\retry.py", line 592, in increment
    raise MaxRetryError(_pool, url, error or ResponseError(cause))
urllib3.exceptions.MaxRetryError: HTTPSConnectionPool(host='api.wandb.ai', port=443): Max retries exceeded with url: /graphql (Caused by NewConnectionError('<urllib3.connection.HTTPSConnection object at 0x0000019319B49430>: Failed to establish a new connection: [Errno 11001] getaddrinfo failed'))

During handling of the above exception, another exception occurred:

Traceback (most recent call last):
  File "C:\Users\wwwle\Documents\Materias_Universidad\Redes Neuronales\env\Keras[3.9]\lib\site-packages\wandb\sdk\lib\retry.py", line 113, in __call__
    result = self._call_fn(*args, **kwargs)
  File "C:\Users\wwwle\Documents\Materias_Universidad\Redes Neuronales\env\Keras[3.9]\lib\site-packages\wandb\sdk\internal\internal_api.py", line 210, in execute
    return self.client.execute(*args, **kwargs)  # type: ignore
  File "C:\Users\wwwle\Documents\Materias_Universidad\Redes Neuronales\env\Keras[3.9]\lib\site-packages\wandb\vendor\gql-0.2.0\wandb_gql\client.py", line 52, in execute
    result = self._get_result(document, *args, **kwargs)
  File "C:\Users\wwwle\Documents\Materias_Universidad\Redes Neuronales\env\Keras[3.9]\lib\site-packages\wandb\vendor\gql-0.2.0\wandb_gql\client.py", line 60, in _get_result
    return self.transport.execute(document, *args, **kwargs)
  File "C:\Users\wwwle\Documents\Materias_Universidad\Redes Neuronales\env\Keras[3.9]\lib\site-packages\wandb\vendor\gql-0.2.0\wandb_gql\transport\requests.py", line 38, in execute
    request = requests.post(self.url, **post_args)
  File "C:\Users\wwwle\Documents\Materias_Universidad\Redes Neuronales\env\Keras[3.9]\lib\site-packages\requests\api.py", line 115, in post
    return request("post", url, data=data, json=json, **kwargs)
  File "C:\Users\wwwle\Documents\Materias_Universidad\Redes Neuronales\env\Keras[3.9]\lib\site-packages\requests\api.py", line 59, in request
    return session.request(method=method, url=url, **kwargs)
  File "C:\Users\wwwle\Documents\Materias_Universidad\Redes Neuronales\env\Keras[3.9]\lib\site-packages\requests\sessions.py", line 587, in request
    resp = self.send(prep, **send_kwargs)
  File "C:\Users\wwwle\Documents\Materias_Universidad\Redes Neuronales\env\Keras[3.9]\lib\site-packages\requests\sessions.py", line 701, in send
    r = adapter.send(request, **kwargs)
  File "C:\Users\wwwle\Documents\Materias_Universidad\Redes Neuronales\env\Keras[3.9]\lib\site-packages\requests\adapters.py", line 565, in send
    raise ConnectionError(e, request=request)
requests.exceptions.ConnectionError: HTTPSConnectionPool(host='api.wandb.ai', port=443): Max retries exceeded with url: /graphql (Caused by NewConnectionError('<urllib3.connection.HTTPSConnection object at 0x0000019319B49430>: Failed to establish a new connection: [Errno 11001] getaddrinfo failed'))
2022-11-07 09:10:12,981 DEBUG   HandlerThread:2632 [handler.py:handle_request():139] handle_request: keepalive
2022-11-07 09:10:18,030 DEBUG   HandlerThread:2632 [handler.py:handle_request():139] handle_request: keepalive
2022-11-07 09:10:27,959 DEBUG   HandlerThread:2632 [handler.py:handle_request():139] handle_request: keepalive
2022-11-07 09:10:33,005 DEBUG   HandlerThread:2632 [handler.py:handle_request():139] handle_request: keepalive
2022-11-07 09:10:38,128 DEBUG   HandlerThread:2632 [handler.py:handle_request():139] handle_request: poll_exit
2022-11-07 09:10:43,175 DEBUG   HandlerThread:2632 [handler.py:handle_request():139] handle_request: keepalive
2022-11-07 09:10:48,192 DEBUG   HandlerThread:2632 [handler.py:handle_request():139] handle_request: keepalive
2022-11-07 09:10:53,211 DEBUG   HandlerThread:2632 [handler.py:handle_request():139] handle_request: keepalive
2022-11-07 09:10:58,239 DEBUG   HandlerThread:2632 [handler.py:handle_request():139] handle_request: keepalive
2022-11-07 09:11:03,281 DEBUG   HandlerThread:2632 [handler.py:handle_request():139] handle_request: keepalive
2022-11-07 09:11:08,328 DEBUG   HandlerThread:2632 [handler.py:handle_request():139] handle_request: keepalive
2022-11-07 09:11:13,356 DEBUG   HandlerThread:2632 [handler.py:handle_request():139] handle_request: keepalive
2022-11-07 09:11:18,378 DEBUG   HandlerThread:2632 [handler.py:handle_request():139] handle_request: keepalive
2022-11-07 09:11:23,406 DEBUG   HandlerThread:2632 [handler.py:handle_request():139] handle_request: keepalive
2022-11-07 09:11:28,461 DEBUG   HandlerThread:2632 [handler.py:handle_request():139] handle_request: keepalive
2022-11-07 09:11:33,481 DEBUG   HandlerThread:2632 [handler.py:handle_request():139] handle_request: keepalive
2022-11-07 09:11:38,494 DEBUG   HandlerThread:2632 [handler.py:handle_request():139] handle_request: keepalive
2022-11-07 09:11:43,528 DEBUG   HandlerThread:2632 [handler.py:handle_request():139] handle_request: keepalive
2022-11-07 09:11:48,583 DEBUG   HandlerThread:2632 [handler.py:handle_request():139] handle_request: keepalive
